Workbook

Sheet 通用文本
A1: ##var | B1: ID | C1: ArgNum | D1: ##备注 | E1: Content
A2: ##type | B2: int | C2: int | E2: array,string
A3: ##group
A4: ## | B4: 文本ID | C4: 参数数量 | E4: 内容是 string 数组类型，数组索引对应 LocalizationType 枚举
A5: ## | D5: 备注:文本ID的第2和3位区分系统 | E5: 0 | F5: 1 | G5: 2 | H5: 3 | I5: 4 | J5: 5 | K5: 6
A6: ## | D6: 自定义的文本ID是1开头 | E6: {=INDEX([1]语言地区!$K:$K,MATCH(E5,[1]语言地区!$J:$J,0))} -> 中国 | F6: {=INDEX([1]语言地区!$K:$K,MATCH(F5,[1]语言地区!$J:$J,0))} -> 欧美 | G6: {=INDEX([1]语言地区!$K:$K,MATCH(G5,[1]语言地区!$J:$J,0))} -> 港澳台 | H6: {=INDEX([1]语言地区!$K:$K,MATCH(H5,[1]语言地区!$J:$J,0))} -> 韩国 | I6: {=INDEX([1]语言地区!$K:$K,MATCH(I5,[1]语言地区!$J:$J,0))} -> 日本 | J6: {=INDEX([1]语言地区!$K:$K,MATCH(J5,[1]语言地区!$J:$J,0))} -> 越南 | K6: {=INDEX([1]语言地区!$K:$K,MATCH(K5,[1]语言地区!$J:$J,0))} -> 印尼
B7: 10000001 | C7: 3 | E7: {0}天{1}时{2}分
B8: 10000002 | C8: 4 | E8: {0}天 {1}：{2}：{3}
B9: 10000003 | C9: 2 | E9: {0}小时{1}分钟
B10: 10000004 | C10: 4 | E10: {0}天{1}时{2}分{3}秒
B11: 10000005 | C11: 3 | E11: {0}时{1}分{2}秒
B12: 10000006 | C12: 3 | E12: {0}分{1}{2}秒
B13: 10000007 | C13: 2 | E13: {0}分{1}秒
B14: 10000008 | E14: 零
B15: 10000009 | E15: 一
B16: 10000010 | E16: 二
B17: 10000011 | E17: 三
B18: 10000012 | E18: 四
B19: 10000013 | E19: 五
B20: 10000014 | E20: 六
B21: 10000015 | E21: 七
B22: 10000016 | E22: 八
B23: 10000017 | E23: 九
B24: 10000018 | E24: 十
B25: 10000019 | E25: 刚刚
B26: 10000020 | C26: 1 | E26: {0}分前
B27: 10000021 | C27: 2 | E27: {0}时{1}分前
B28: 10000022 | C28: 1 | E28: {0}天前
B29: 10000023 | C29: 1 | E29: {0}小时前
B30: 10000024 | C30: 1 | E30: {0}千
B31: 10000025 | C31: 1 | E31: {0}万
B32: 10000026 | C32: 1 | E32: {0}亿
B33: 10000027 | E33: 开始游戏 | F33: Start Game | G33: 開始遊戲 | H33: 게임 시작 | I33: ゲーム開始 | J33: Bắt đầu trò chơi | K33: Mulai Permainan
B34: 10000028 | E34: 退出游戏 | F34: Exit Game | G34: 退出遊戲 | H34: 게임 종료 | I34: ゲーム終了 | J34: Thoát trò chơi | K34: Keluar Permainan
A35: ##
A36: ## | D36: 主界面功能按钮
B37: 10100001 | D37: 主界面功能按钮 | E37: 商城
B38: 10100002 | D38: 主界面功能按钮 | E38: 角色
B39: 10100003 | D39: 主界面功能按钮 | E39: 主界面
B40: 10100004 | D40: 主界面功能按钮 | E40: 公会
...

Sheet 道具表文本
A1: ##var | B1: ID | C1: ArgNum | D1: ##备注 | E1: Content
A2: ##type | B2: int | C2: int | E2: array,string
A3: ##group
A4: ## | B4: 文本ID | C4: 参数数量 | E4: 内容是 string 数组类型，数组索引对应 LocalizationType 枚举
A5: ## | E5: 0 | F5: 1 | G5: 2 | H5: 3 | I5: 4 | J5: 5 | K5: 6
A6: ## | D6: 道具表的文本ID是4开头 | E6: {=INDEX([1]语言地区!$K:$K,MATCH(E5,[1]语言地区!$J:$J,0))} -> 中国 | F6: {=INDEX([1]语言地区!$K:$K,MATCH(F5,[1]语言地区!$J:$J,0))} -> 欧美 | G6: {=INDEX([1]语言地区!$K:$K,MATCH(G5,[1]语言地区!$J:$J,0))} -> 港澳台 | H6: {=INDEX([1]语言地区!$K:$K,MATCH(H5,[1]语言地区!$J:$J,0))} -> 韩国 | I6: {=INDEX([1]语言地区!$K:$K,MATCH(I5,[1]语言地区!$J:$J,0))} -> 日本 | J6: {=INDEX([1]语言地区!$K:$K,MATCH(J5,[1]语言地区!$J:$J,0))} -> 越南 | K6: {=INDEX([1]语言地区!$K:$K,MATCH(K5,[1]语言地区!$J:$J,0))} -> 印尼
B7: 40000001 | D7: 道具配置表 | E7: 金币
B8: 40000002 | D8: 道具配置表 | E8: 钻石
B9: 40000003 | D9: 道具配置表 | E9: 体力
B10: 40000004 | D10: 道具配置表 | E10: 经验
B11: 40000005 | D11: 道具配置表 | E11: 发型
B12: 40000006 | D12: 道具配置表 | E12: 外套
B13: 40000007 | D13: 道具配置表 | E13: 上衣
B14: 40000008 | D14: 道具配置表 | E14: 裙子
B15: 40000009 | D15: 道具配置表 | E15: 袜子
B16: 40000010 | D16: 道具配置表 | E16: 鞋子
B17: 40000011 | D17: 道具配置表 | E17: 发饰
B18: 40000012 | D18: 道具配置表 | E18: 中秋节发饰
... B20: 40000014 | D20: 道具配置表 | E20: 礼包
A21: ## | B21: 道具的提示 从41开始
B22: 41000001 | D22: 金币 | E22: 基础货币，用途很广，在很多地方需要用到。
B23: 41000002 | D23: 钻石 | E23: 价值连城，比金币有着更大的购买力！
B24: 41000003 | D24: 体力 | E24: 挑战关卡或者快速游历时消耗。
B25: 41000004 | D25: 经验 | E25: 累计经验提升主角等级

Sheet 自动生成代码文本
A1: ##var | B1: ID | C1: ArgNum | D1: ##备注 | E1: Content
A2: ##type | B2: int | C2: int | E2: array,string
A3: ##group
A4: ## | B4: 文本ID | C4: 参数数量 | E4: 内容是 string 数组类型，数组索引对应 LocalizationType 枚举
A5: ## | D5: 备注 | E5: 0 | F5: 1 | G5: 2 | H5: 3 | I5: 4 | J5: 5 | K5: 6
A6: ## | D6: 自动生成代码文本的文本ID是2开头 | E6: {=INDEX([1]语言地区!$K:$K,MATCH(E5,[1]语言地区!$J:$J,0))} -> 中国 | F6: {=INDEX([1]语言地区!$K:$K,MATCH(F5,[1]语言地区!$J:$J,0))} -> 欧美 | G6: {=INDEX([1]语言地区!$K:$K,MATCH(G5,[1]语言地区!$J:$J,0))} -> 港澳台 | H6: {=INDEX([1]语言地区!$K:$K,MATCH(H5,[1]语言地区!$J:$J,0))} -> 韩国 | I6: {=INDEX([1]语言地区!$K:$K,MATCH(I5,[1]语言地区!$J:$J,0))} -> 日本 | J6: {=INDEX([1]语言地区!$K:$K,MATCH(J5,[1]语言地区!$J:$J,0))} -> 越南 | K6: {=INDEX([1]语言地区!$K:$K,MATCH(K5,[1]语言地区!$J:$J,0))} -> 印尼

Sheet 自动生成组件文本
A1: ##var | B1: ID | C1: ArgNum | D1: ##备注 | E1: Content
A2: ##type | B2: int | C2: int | E2: array,string
A3: ##group
A4: ## | B4: 文本ID | C4: 参数数量 | E4: 内容是 string 数组类型，数组索引对应 LocalizationType 枚举
A5: ## | D5: 备注 | E5: 0 | F5: 1 | G5: 2 | H5: 3 | I5: 4 | J5: 5 | K5: 6
A6: ## | D6: 自动生成组件文本文本的文本ID是3开头 | E6: {=INDEX([1]语言地区!$K:$K,MATCH(E5,[1]语言地区!$J:$J,0))} -> 中国 | F6: {=INDEX([1]语言地区!$K:$K,MATCH(F5,[1]语言地区!$J:$J,0))} -> 欧美 | G6: {=INDEX([1]语言地区!$K:$K,MATCH(G5,[1]语言地区!$J:$J,0))} -> 港澳台 | H6: {=INDEX([1]语言地区!$K:$K,MATCH(H5,[1]语言地区!$J:$J,0))} -> 韩国 | I6: {=INDEX([1]语言地区!$K:$K,MATCH(I5,[1]语言地区!$J:$J,0))} -> 日本 | J6: {=INDEX([1]语言地区!$K:$K,MATCH(J5,[1]语言地区!$J:$J,0))} -> 越南 | K6: {=INDEX([1]语言地区!$K:$K,MATCH(K5,[1]语言地区!$J:$J,0))} -> 印尼

Sheet 登录错误_服务器
A1: ##var | B1: ID | C1: ArgNum | D1: ##备注 | E1: Content
A2: ##type | B2: int | C2: int | E2: array,string
A3: ##group
A4: ## | B4: 文本ID | C4: 参数数量 | E4: 内容是 string 数组类型，数组索引对应 LocalizationType 枚举
A5: ## | D5: 备注 | E5: 0 | F5: 1 | G5: 2 | H5: 3 | I5: 4 | J5: 5 | K5: 6
A6: ## | D6: 服务器错误码文本，低位数自定义 | E6: {=INDEX([1]语言地区!$K:$K,MATCH(E5,[1]语言地区!$J:$J,0))} -> 中国 | F6: {=INDEX([1]语言地区!$K:$K,MATCH(F5,[1]语言地区!$J:$J,0))} -> 欧美 | G6: {=INDEX([1]语言地区!$K:$K,MATCH(G5,[1]语言地区!$J:$J,0))} -> 港澳台 | H6: {=INDEX([1]语言地区!$K:$K,MATCH(H5,[1]语言地区!$J:$J,0))} -> 韩国 | I6: {=INDEX([1]语言地区!$K:$K,MATCH(I5,[1]语言地区!$J:$J,0))} -> 日本 | J6: {=INDEX([1]语言地区!$K:$K,MATCH(J5,[1]语言地区!$J:$J,0))} -> 越南 | K6: {=INDEX([1]语言地区!$K:$K,MATCH(K5,[1]语言地区!$J:$J,0))} -> 印尼
A7: ## | D7: 账号相关错误码
B8: 1001 | D8: 账号已存在 | E8: 账号已存在
B9: 1002 | D9: 未知错误 | E9: 未知错误
B10: 1003 | D10: 参数无效，账号或密码为空 | E10: 参数无效，账号或密码为空
B11: 1004 | D11: 密码错误，请重试 | E11: 密码错误，请重试
B12: 1005 | D12: 账号不存在 | E12: 账号不存在
B13: 1006 | D13: 账号已存在但密码错误 | E13: 账号已存在但密码错误
B14: 1007 | D14: 位置错误 | E14: 位置错误
B15: 1008 | D15: 参数无效，账号或密码为空 | E15: 参数无效，账号或密码为空
B16: 1009 | D16: 账号已在线 | E16: 账号已在线
B17: 1010 | D17: 账号或密码不能为空 | E17: 账号或密码不能为空
B18: 1011 | D18: 账号格式不正确，需6-24位字母和数字 | E18: 账号格式不正确，需6-24位字母和数字
B19: 1012 | D19: 密码长度至少需8位 | E19: 密码长度至少需8位
... B22: 1015 | D22: 登录Token验证失败 | E22: 登录Token验证失败
A23: ##
A24: ## | D24: 角色相关错误码
B25: 2001 | D25: 创建角色成功 | E25: 创建角色成功
B26: 2002 | D26: 角色配置不存在 | E26: 角色配置不存在
B27: 2003 | D27: 角色名已存在 | E27: 角色名已存在
B28: 2004 | D28: 角色名无效（为空或包含非法字符） | E28: 角色名无效（为空或包含非法字符）
B29: 2005 | D29: 性别参数无效 | E29: 性别参数无效
B30: 2006 | D30: 角色不存在 | E30: 角色不存在
B31: 2007 | D31: 角色不属于该账号 | E31: 角色不属于该账号
B32: 2008 | D32: 角色名长度不符，请使用中文2-6字，英文4-12字符 | E32: 角色名长度不符，请使用中文2-6字，英文4-12字符
B33: 2009 | D33: 角色名字含有非法字符 | E33: 角色名字含有非法字符
A34: ##
A35: ## | D35: 系统开放
B36: 3001 | D36: 系统开放查询错误
A37: ##
A38: ## | D38: 组队
B39: 4001 | D39: 房间参数无效
B40: 4002 | D40: 房间不存在
B41: 4003 | D41: 玩家已在房间中
B42: 4004 | D42: 房间玩家数量配置无效
...
